<?xml version="1.0" ?>
<sdf version="1.6">
  <model name="three_link">

        <static>false</static>

        <link name='lower'>
            <pose>0 0 0 0 0 0</pose>
            <inertial>
                <inertia>
                    <ixx>0.01</ixx>
                    <ixy>0</ixy>
                    <ixz>0</ixz>
                    <iyy>0.01</iyy>
                    <iyz>0</iyz>
                    <izz>0.01</izz>
                </inertia>
                <mass>50</mass>
            </inertial>

            <collision name='collision'>
              <geometry>
                <box>
                  <size>.1 .1 1</size>
                </box>
              </geometry>
            </collision>

            <visual name='visual'>
              <geometry>
                <box>
                  <size>.1 .1 1</size>
                </box>
              </geometry>
            </visual>

        </link>

        <link name='mid'>
            <pose>0 0 .70 0 0 0</pose>

            <collision name='collision'>
              <geometry>
                <box>
                  <size>.1 .1 .5</size>
                </box>
              </geometry>
            </collision>

            <visual name='visual'>
              <geometry>
                <box>
                  <size>.1 .1 .5</size>
                </box>
              </geometry>
            </visual>

        </link>

        <link name='top'>
            <pose>0 0 1.15 0 0 0</pose>

            <collision name='collision'>
              <geometry>
                <box>
                  <size>.1 .1 .5</size>
                </box>
              </geometry>
            </collision>

            <visual name='visual'>
              <geometry>
                <box>
                  <size>.1 .1 .5</size>
                </box>
              </geometry>
            </visual>

        </link>
      <joint name="fixed" type="fixed">
      <pose>0 0 0 0 0 0</pose>
        <child>low</child>
        <parent>world</parent>
      </joint>

      <joint type="revolute" name="low_mid">
        <pose>0 0 -0.225 0 0 0</pose>
        <child>mid</child>
        <parent>lower</parent>
        <axis>
          <xyz>0 0 1</xyz>
        </axis>
      </joint>
      <joint type="revolute" name="mid_top">
        <pose>0 0 -0.225 0 0 0</pose>
        <child>top</child>
        <parent>mid</parent>
        <axis>
          <xyz>0 0 1</xyz>
        </axis>
      </joint>
  </model>
</sdf>
