<?xml version="1.0"?> 
<sdf version="1.4">
  <world name="default">

    <!-- Ground Plane -->
    <include>
      <uri>model://ground_plane</uri>
    </include>

    <include>
      <uri>model://sun</uri>
    </include>
    <model name="my_robot">

        <static>false</static>


        <link name='chassis'>
            <pose>0 0 .1 0 0 0</pose>

            <collision name='collision'>
              <geometry>
                <box>
                  <size>.4 .2 .1</size>
                </box>
              </geometry>
            </collision>

            <visual name='visual'>
              <geometry>
                <box>
                  <size>.4 .2 .1</size>
                </box>
              </geometry>
            </visual>

            <collision name='caster_collision'>
            <pose>-0.15 0 -0.05 0 0 0</pose>
            <geometry>
                <sphere>
                <radius>.05</radius>
              </sphere>
            </geometry>

            <surface>
              <friction>
                <ode>
                  <mu>0</mu>
                  <mu2>0</mu2>
                  <slip1>1.0</slip1>
                  <slip2>1.0</slip2>
                </ode>
              </friction>
            </surface>
          </collision>

          <visual name='caster_visual'>
            <pose>-0.15 0 -0.05 0 0 0</pose>
            <geometry>
              <sphere>
                <radius>.05</radius>
              </sphere>
            </geometry>
          </visual>

        </link>

      <link name="left_wheel">
        <pose>0.1 0.13 0.1 0 1.5707 1.5707</pose>
        <collision name="collision">
          <geometry>
            <cylinder>
              <radius>.1</radius>
              <length>.05</length>
            </cylinder>
          </geometry>
        </collision>
        <visual name="visual">
          <geometry>
            <cylinder>
              <radius>.1</radius>
              <length>.05</length>
            </cylinder>
          </geometry>
        </visual>
      </link>

      <link name="right_wheel">
        <pose>0.1 -0.13 0.1 0 1.5707 1.5707</pose>
        <collision name="collision">
          <geometry>
            <cylinder>
              <radius>.1</radius>
              <length>.05</length>
            </cylinder>
          </geometry>
        </collision>
        <visual name="visual">
          <geometry>
            <cylinder>
              <radius>.1</radius>
              <length>.05</length>
            </cylinder>
          </geometry>
        </visual>
      </link>



      <joint type="revolute" name="left_wheel_hinge">
        <pose>0 0 -0.03 0 0 0</pose>
        <child>left_wheel</child>
        <parent>chassis</parent>
        <axis>
          <xyz>0 1 0</xyz>
        </axis>
      </joint>

      <joint type="revolute" name="right_wheel_hinge">
        <pose>0 0 0.03 0 0 0</pose>
        <child>right_wheel</child>
        <parent>chassis</parent>
        <axis>
          <xyz>0 1 0</xyz>
        </axis>
      </joint>

    <include>
        <uri>model://hokuyo</uri>
        <pose>0.2 0 0.2 0 0 0</pose>
    </include>
    
    <joint name="hokuyo_joint" type="fixed">
      <child>hokuyo::link</child>
      <parent>chassis</parent>
    </joint>
    
    <link name="camera_link">
			<pose>0 0 0.035 0 0 0</pose>
      		<visual name="visual">
		        <geometry>
		          <mesh>
		            <uri>model://hokuyo/meshes/hokuyo.dae</uri>
		          </mesh>
		        </geometry>
		    </visual>
		    <collision name="collision-base">
		        <pose>0 0 -0.0145 0 0 0</pose>
		        <geometry>
		          <box>
		            <size>0.05 0.05 0.041</size>
		          </box>
		        </geometry>
		    </collision>
		    <collision name="collision-top">
		        <pose>0 0 0.0205 0 0 0</pose>
		        <geometry>
		          <cylinder>
		            <radius>0.021</radius>
		            <length>0.029</length>
		          </cylinder>
		        </geometry>
		    </collision>
			<sensor type="camera" name="camera1">
				<logical_camera>
					<near>0.05</near>
					<far>10.0</far>
					<horizontal_fov>1.0</horizontal_fov>
					<aspect_ratio>1.8</aspect_ratio>
				</logical_camera>
				 <visualize>true</visualize>
				<always_on>true</always_on>
				<update_rate>10</update_rate>
				<plugin name="camera_controller" filename="libgazebo_ros_camera.so">
					<updateRate>0.0</updateRate>
			        <cameraName>my_camera/camera1</cameraName>
			        <frameName>camera</frameName>
			        <hackBaseline>0.07</hackBaseline>
			        <distortionK1>0.0</distortionK1>
			        <distortionK2>0.0</distortionK2>
			        <distortionK3>0.0</distortionK3>
			        <distortionT1>0.0</distortionT1>
        			<distortionT2>0.0</distortionT2>
				</plugin>
			</sensor>
		</link>

        <joint name="camera_joint" type="fixed">
            <child>camera_link</child>
            <parent>chassis</parent>
        </joint>
<plugin name="myrobot_package" filename="libmyrobot_package.so"/>
  </model>
  </world>
</sdf>
